<?xml version="1.0"?>
<robot name="dd_robot">
    <!-- Creating a dummy link for the base_link inertia-->
    <link name="base_link_dummy_workaround">
    </link>
    <joint name="base_link_dummy_joint" type="fixed">
        <parent link="base_link_dummy_workaround" />
        <child link="base_link" />
    </joint>
    <!-- Base Link -->
    <link name="base_link">
        <visual>
            <origin xyz="0 0 0" rpy="0 0 0" />
            <geometry>
                <box size="0.5 0.5 0.25" />
            </geometry>
            <material name="blue">
                <color rgba="0 0.5 1 1" />
            </material>
        </visual>
        <!-- Base Collision -->
        <collision>
            <origin xyz="0 0 0" rpy="0 0 0" />
            <geometry>
                <box size="0.5 0.5 0.25" />
            </geometry>
        </collision>
        <!-- Base Inertia -->
        <inertial>
            <mass value="5" />
            <inertia ixx="0.13" ixy="0.0" ixz="0.0"
                iyy="0.21" iyz="0.0" izz="0.13" />
        </inertial>

        <visual name="caster">
            <origin xyz="0.2 0 -0.125" rpy="0 0 0" />
            <geometry>
                <sphere radius="0.05" />
            </geometry>
        </visual>
        <!-- Caster Collision -->
        <collision>
            <origin xyz="0.2 0 -0.125" rpy="0 0 0" />
            <geometry>
                <sphere radius="0.05" />
            </geometry>
        </collision>
        <!-- Caster Inertia -->
        <inertial>
            <mass value="0.5" />
            <inertia ixx="0.0001" ixy="0.0" ixz="0.0"
                iyy="0.0001" iyz="0.0" izz="0.13" />
        </inertial>
    </link>
    <!-- Gazebo specifics for the base_link -->
    <gazebo reference="base_link">
        <material>Gazebo/Blue</material>
        <pose>0 0 3 0 0 0</pose>
    </gazebo>

    <!-- Right Wheel -->
    <link name="right_wheel">
        <visual>
            <origin xyz="0 0 0" rpy="1.570795 0 0" />
            <geometry>
                <cylinder length="0.1" radius="0.2" />
            </geometry>
            <material name="black">
                <color rgba="0.05 0.05 0.05 1" />
            </material>
        </visual>
        <!-- Right Wheel Collision -->
        <collision>
            <origin xyz="0 0 0" rpy="1.570795 0 0" />
            <geometry>
                <cylinder length="0.1" radius="0.2" />
            </geometry>
        </collision>
        <!-- Right Wheel Inertia -->
        <inertial>
            <mass value="0.5" />
            <inertia ixx="0.01" ixy="0.0" ixz="0.0"
                iyy="0.005" iyz="0.0" izz="0.005" />
        </inertial>
    </link>

    <joint name="joint_right_wheel" type="continuous">
        <parent link="base_link" />
        <child link="right_wheel" />
        <origin xyz="0 -0.3 0" rpy="0 0 0" />
        <axis xyz="0 1 0" />
    </joint>

    <!-- Gazebo specifics for the right wheel -->
    <gazebo reference="right_wheel">
        <material>Gazebo/Black</material>
    </gazebo>

    <!-- Left Wheel -->
    <link name="left_wheel">
        <visual>
            <origin xyz="0 0 0" rpy="1.570795 0 0" />
            <geometry>
                <cylinder length="0.1" radius="0.2" />
            </geometry>
            <material name="black" />
        </visual>
        <!-- Left Wheel Collision -->
        <collision>
            <origin xyz="0 0 0" rpy="1.570795 0 0" />
            <geometry>
                <cylinder length="0.1" radius="0.2" />
            </geometry>
        </collision>
        <!-- Left Wheel Inertia -->
        <inertial>
            <mass value="0.5" />
            <inertia ixx="0.01" ixy="0.0" ixz="0.0"
                iyy="0.005" iyz="0.0" izz="0.005" />
        </inertial>
    </link>

    <!-- Gazebo specifics for the left wheel -->
    <gazebo reference="left_wheel">
        <material>Gazebo/Black</material>
    </gazebo>

    <joint name="joint_left_wheel" type="continuous">
        <parent link="base_link" />
        <child link="left_wheel" />
        <origin xyz="0 0.3 0" rpy="0 0 0" />
        <axis xyz="0 1 0" />
    </joint>

</robot>

